#VRML_SIM R2023b utf8

EXTERNPROTO "https://raw.githubusercontent.com/cyberbotics/webots/R2023b/projects/appearances/protos/OsbWood.proto"
EXTERNPROTO "https://raw.githubusercontent.com/cyberbotics/webots/R2023b/projects/objects/floors/protos/RectangleArena.proto"
EXTERNPROTO "https://raw.githubusercontent.com/cyberbotics/webots/R2023b/projects/objects/backgrounds/protos/TexturedBackground.proto"
EXTERNPROTO "https://raw.githubusercontent.com/cyberbotics/webots/R2023b/projects/objects/backgrounds/protos/TexturedBackgroundLight.proto"

WorldInfo {
  info [
    "In this example, the robot moves down a slope."
    "The altimeter is used to record the robots height."
  ]
  title "Altimeter"
  basicTimeStep 8
  contactProperties [
    ContactProperties {
      material2 "body"
      coulombFriction [
        0
      ]
      softCFM 0.1
    }
  ]
}
Viewpoint {
  orientation 0.03428182353017453 -0.3391213818691208 -0.9401177824797401 0.5519546495099913
  position -0.40267117217885645 0.4103058264341395 0.17572085617397598
}
TexturedBackground {
}
TexturedBackgroundLight {
}
RectangleArena {
}
PointLight {
  attenuation 0 0 1
  intensity 0.6
  location 0.6 0 0
}
DEF SLOPE Solid {
  translation 0 0.01 0.15
  rotation 0 1 0 -0.4
  children [
    Shape {
      appearance OsbWood {
        textureTransform TextureTransform {
          scale 0.5 2
        }
      }
      geometry DEF BOX0 Box {
        size 0.8 0.2 0.02
      }
    }
  ]
  name "green box"
  boundingObject USE BOX0
}
Robot {
  translation 0.285539 0.018358 0.279764
  rotation -0.21640194479782288 -0.03695359057347357 0.9756047511320597 2.90365
  children [
    Altimeter {
    }
    Pose {
      translation 0 0 0.0415
      children [
        Shape {
          appearance PBRAppearance {
            baseColor 0.32549 0.207843 0.211765
            roughness 1
            metalness 0
          }
          geometry DEF BODY Cylinder {
            height 0.08
            radius 0.045
          }
        }
      ]
    }
    HingeJoint {
      jointParameters HingeJointParameters {
        position 16.720002454100733
        axis 0 1 0
        anchor 0 0 0.025
      }
      device [
        RotationalMotor {
          name "left wheel motor"
          consumptionFactor 70
        }
        PositionSensor {
          name "left wheel sensor"
        }
      ]
      endPoint Solid {
        translation -4.01464e-07 0.045 0.0250001
        rotation -0.6929920029408114 0.6929920556610428 -0.19880667657491952 2.7490969685862408
        children [
          DEF WHEEL Pose {
            rotation 0.577656895078166 0.5771968951617173 -0.5771968951617173 -2.093935
            children [
              Shape {
                appearance PBRAppearance {
                  baseColor 0.584314 0.486275 0.490196
                  roughness 1
                  metalness 0
                }
                geometry Cylinder {
                  height 0.01
                  radius 0.025
                }
              }
            ]
          }
        ]
        name "left wheel"
        boundingObject USE WHEEL
        physics DEF PHYSICS_WHEEL Physics {
          density -1
          mass 0.05
        }
      }
    }
    HingeJoint {
      jointParameters HingeJointParameters {
        position 16.720002443680347
        axis 0 1 0
        anchor 0 0 0.025
      }
      device [
        RotationalMotor {
          name "right wheel motor"
          consumptionFactor 70
        }
        PositionSensor {
          name "right wheel sensor"
        }
      ]
      endPoint Solid {
        translation -4.01966e-07 -0.045 0.025
        rotation -0.6929920024024309 0.6929920551226624 -0.19880668032824822 2.749096961364995
        children [
          USE WHEEL
        ]
        boundingObject USE WHEEL
        physics USE PHYSICS_WHEEL
      }
    }
    DistanceSensor {
      translation 0.042 0.02 0.063
      rotation 0 0 -1 -0.499
      children [
        DEF SENSOR Pose {
          rotation 0.577656895078166 0.5771968951617173 -0.5771968951617173 -2.09394
          children [
            Shape {
              appearance PBRAppearance {
                baseColor 0.858824 0.662745 0.670588
                roughness 1
                metalness 0
              }
              geometry Cylinder {
                height 0.004
                radius 0.008
              }
            }
          ]
        }
      ]
      name "ds0"
      lookupTable [
        0 1024 0
        0.05 1024 0
        0.15 0 0
      ]
      numberOfRays 2
    }
    DistanceSensor {
      translation 0.042 -0.02 0.063
      rotation 0.4551608169186531 -0.11622195325153013 -0.8827916449108155 0.5631190000000004
      children [
        DEF SENSOR Pose {
          rotation 0.577656895078166 0.5771968951617173 -0.5771968951617173 -2.09
          children [
            Shape {
              appearance PBRAppearance {
                baseColor 0.858824 0.662745 0.670588
                roughness 1
                metalness 0
              }
              geometry Cylinder {
                height 0.005
                radius 0.008
              }
            }
          ]
        }
      ]
      name "ds1"
      lookupTable [
        0 1024 0
        0.05 1024 0
        0.15 0 0
      ]
      numberOfRays 2
    }
    Pose {
      translation 0.036 0 0.025
      rotation 0.25062480957341265 -0.9352306483844017 -0.2500616706910165 1.638
      children [
        Shape {
          appearance PBRAppearance {
            baseColor 0.596078 0.403922 0.407843
            roughness 1
            metalness 0
          }
          geometry Cylinder {
            height 0.02
            radius 0.007
          }
        }
      ]
      translationStep -0.02
    }
    DEF EYES Pose {
      translation 0.042 0.02 0.063
      rotation 0.3782629770617555 0.6545669603064062 -0.6545679603063456 -2.418345307179586
      children [
        Shape {
          appearance PBRAppearance {
            baseColor 0.407843 0.313726 0.321569
            roughness 1
            metalness 0
          }
          geometry Cylinder {
            height 0.006
            radius 0.004
          }
        }
      ]
    }
    DEF EYES Pose {
      translation 0.042 -0.02 0.063
      rotation -0.7748811695668775 -0.446968097809816 0.44696609780937835 1.82313
      children [
        Shape {
          appearance PBRAppearance {
            baseColor 0.407843 0.313726 0.321569
            roughness 1
            metalness 0
          }
          geometry Cylinder {
            height 0.0078
            radius 0.004
          }
        }
      ]
    }
  ]
  name "MyBot"
  contactMaterial "body"
  boundingObject Pose {
    translation 0 0 0.0415
    rotation 0 0 1 -1.570796
    children [
      USE BODY
    ]
  }
  physics Physics {
    density -1
    mass 0.5
  }
  controller ""
}
